[2023-01-20T12:37:37.991+0000] {taskinstance.py:1087} INFO - Dependencies all met for <TaskInstance: test_dag1.t2 manual__2023-01-20T12:37:35.837152+00:00 [queued]>
[2023-01-20T12:37:38.006+0000] {taskinstance.py:1087} INFO - Dependencies all met for <TaskInstance: test_dag1.t2 manual__2023-01-20T12:37:35.837152+00:00 [queued]>
[2023-01-20T12:37:38.008+0000] {taskinstance.py:1283} INFO - 
--------------------------------------------------------------------------------
[2023-01-20T12:37:38.008+0000] {taskinstance.py:1284} INFO - Starting attempt 1 of 3
[2023-01-20T12:37:38.009+0000] {taskinstance.py:1285} INFO - 
--------------------------------------------------------------------------------
[2023-01-20T12:37:38.028+0000] {taskinstance.py:1304} INFO - Executing <Task(PythonOperator): t2> on 2023-01-20 12:37:35.837152+00:00
[2023-01-20T12:37:38.039+0000] {standard_task_runner.py:55} INFO - Started process 697 to run task
[2023-01-20T12:37:38.044+0000] {standard_task_runner.py:82} INFO - Running: ['***', 'tasks', 'run', 'test_dag1', 't2', 'manual__2023-01-20T12:37:35.837152+00:00', '--job-id', '147', '--raw', '--subdir', 'DAGS_FOLDER/test-dag1.py', '--cfg-path', '/tmp/tmphnp5s466']
[2023-01-20T12:37:38.045+0000] {standard_task_runner.py:83} INFO - Job 147: Subtask t2
[2023-01-20T12:37:38.133+0000] {task_command.py:389} INFO - Running <TaskInstance: test_dag1.t2 manual__2023-01-20T12:37:35.837152+00:00 [running]> on host 3f5f9ed80e7e
[2023-01-20T12:37:38.208+0000] {taskinstance.py:1513} INFO - Exporting the following env vars:
AIRFLOW_CTX_DAG_OWNER=himanshi
AIRFLOW_CTX_DAG_ID=test_dag1
AIRFLOW_CTX_TASK_ID=t2
AIRFLOW_CTX_EXECUTION_DATE=2023-01-20T12:37:35.837152+00:00
AIRFLOW_CTX_TRY_NUMBER=1
AIRFLOW_CTX_DAG_RUN_ID=manual__2023-01-20T12:37:35.837152+00:00
[2023-01-20T12:37:38.210+0000] {logging_mixin.py:137} INFO - Hello Himanshi1 from Python opertor
[2023-01-20T12:37:38.218+0000] {taskinstance.py:1772} ERROR - Task failed with exception
Traceback (most recent call last):
  File "/home/airflow/.local/lib/python3.7/site-packages/airflow/operators/python.py", line 175, in execute
    return_value = self.execute_callable()
  File "/home/airflow/.local/lib/python3.7/site-packages/airflow/operators/python.py", line 192, in execute_callable
    return self.python_callable(*self.op_args, **self.op_kwargs)
  File "/opt/airflow/dags/test-dag1.py", line 14, in sayHi
    ti.xcom_push(key='Name', value={name})
  File "/home/airflow/.local/lib/python3.7/site-packages/airflow/utils/session.py", line 75, in wrapper
    return func(*args, session=session, **kwargs)
  File "/home/airflow/.local/lib/python3.7/site-packages/airflow/models/taskinstance.py", line 2301, in xcom_push
    session=session,
  File "/home/airflow/.local/lib/python3.7/site-packages/airflow/utils/session.py", line 72, in wrapper
    return func(*args, **kwargs)
  File "/home/airflow/.local/lib/python3.7/site-packages/airflow/models/xcom.py", line 240, in set
    map_index=map_index,
  File "/home/airflow/.local/lib/python3.7/site-packages/airflow/models/xcom.py", line 627, in serialize_value
    return json.dumps(value, cls=XComEncoder).encode("UTF-8")
  File "/usr/local/lib/python3.7/json/__init__.py", line 238, in dumps
    **kw).encode(obj)
  File "/home/airflow/.local/lib/python3.7/site-packages/airflow/utils/json.py", line 176, in encode
    return super().encode(o)
  File "/usr/local/lib/python3.7/json/encoder.py", line 199, in encode
    chunks = self.iterencode(o, _one_shot=True)
  File "/usr/local/lib/python3.7/json/encoder.py", line 257, in iterencode
    return _iterencode(o, 0)
  File "/home/airflow/.local/lib/python3.7/site-packages/airflow/utils/json.py", line 153, in default
    CLASSNAME: o.__module__ + "." + o.__class__.__qualname__,
AttributeError: 'set' object has no attribute '__module__'
[2023-01-20T12:37:38.230+0000] {taskinstance.py:1327} INFO - Marking task as UP_FOR_RETRY. dag_id=test_dag1, task_id=t2, execution_date=20230120T123735, start_date=20230120T123737, end_date=20230120T123738
[2023-01-20T12:37:38.245+0000] {standard_task_runner.py:105} ERROR - Failed to execute job 147 for task t2 ('set' object has no attribute '__module__'; 697)
[2023-01-20T12:37:38.296+0000] {local_task_job.py:159} INFO - Task exited with return code 1
[2023-01-20T12:37:38.317+0000] {taskinstance.py:2582} INFO - 0 downstream tasks scheduled from follow-on schedule check
