[2023-01-12T11:04:05.597+0000] {taskinstance.py:1087} INFO - Dependencies all met for <TaskInstance: test_dag1.t3 manual__2023-01-12T11:04:00.956128+00:00 [queued]>
[2023-01-12T11:04:05.620+0000] {taskinstance.py:1087} INFO - Dependencies all met for <TaskInstance: test_dag1.t3 manual__2023-01-12T11:04:00.956128+00:00 [queued]>
[2023-01-12T11:04:05.621+0000] {taskinstance.py:1283} INFO - 
--------------------------------------------------------------------------------
[2023-01-12T11:04:05.622+0000] {taskinstance.py:1284} INFO - Starting attempt 1 of 3
[2023-01-12T11:04:05.622+0000] {taskinstance.py:1285} INFO - 
--------------------------------------------------------------------------------
[2023-01-12T11:04:05.636+0000] {taskinstance.py:1304} INFO - Executing <Task(PythonOperator): t3> on 2023-01-12 11:04:00.956128+00:00
[2023-01-12T11:04:05.642+0000] {standard_task_runner.py:55} INFO - Started process 28692 to run task
[2023-01-12T11:04:05.648+0000] {standard_task_runner.py:82} INFO - Running: ['***', 'tasks', 'run', 'test_dag1', 't3', 'manual__2023-01-12T11:04:00.956128+00:00', '--job-id', '94', '--raw', '--subdir', 'DAGS_FOLDER/test-dag1.py', '--cfg-path', '/tmp/tmpwb2k5nrk']
[2023-01-12T11:04:05.650+0000] {standard_task_runner.py:83} INFO - Job 94: Subtask t3
[2023-01-12T11:04:05.741+0000] {task_command.py:389} INFO - Running <TaskInstance: test_dag1.t3 manual__2023-01-12T11:04:00.956128+00:00 [running]> on host 5ad6c27f6c76
[2023-01-12T11:04:05.829+0000] {taskinstance.py:1513} INFO - Exporting the following env vars:
AIRFLOW_CTX_DAG_OWNER=himanshi
AIRFLOW_CTX_DAG_ID=test_dag1
AIRFLOW_CTX_TASK_ID=t3
AIRFLOW_CTX_EXECUTION_DATE=2023-01-12T11:04:00.956128+00:00
AIRFLOW_CTX_TRY_NUMBER=1
AIRFLOW_CTX_DAG_RUN_ID=manual__2023-01-12T11:04:00.956128+00:00
[2023-01-12T11:04:05.854+0000] {taskinstance.py:1772} ERROR - Task failed with exception
Traceback (most recent call last):
  File "/home/airflow/.local/lib/python3.7/site-packages/airflow/operators/python.py", line 175, in execute
    return_value = self.execute_callable()
  File "/home/airflow/.local/lib/python3.7/site-packages/airflow/operators/python.py", line 192, in execute_callable
    return self.python_callable(*self.op_args, **self.op_kwargs)
  File "/opt/airflow/dags/test-dag1.py", line 18, in fetch_name
    print('Name fetched from xcom '+ {name})
TypeError: can only concatenate str (not "set") to str
[2023-01-12T11:04:05.884+0000] {taskinstance.py:1327} INFO - Marking task as UP_FOR_RETRY. dag_id=test_dag1, task_id=t3, execution_date=20230112T110400, start_date=20230112T110405, end_date=20230112T110405
[2023-01-12T11:04:05.906+0000] {standard_task_runner.py:105} ERROR - Failed to execute job 94 for task t3 (can only concatenate str (not "set") to str; 28692)
[2023-01-12T11:04:05.941+0000] {local_task_job.py:159} INFO - Task exited with return code 1
[2023-01-12T11:04:05.962+0000] {taskinstance.py:2582} INFO - 0 downstream tasks scheduled from follow-on schedule check
